Workbook

Sheet 2024 - Mensile Fer-Fest
B1: PROPOSTE DI PAGAMENTO | AD1: PAGAMENTI EFFETTUATI
B2: GENNAIO | D2: FEBBRAIO | F2: MARZO | H2: APRILE | J2: MAGGIO | L2: GIUGNO | N2: LUGLIO | P2: AGOSTO | R2: SETTEMBRE | T2: OTTOBRE | V2: NOVEMBRE | X2: DICEMBRE | Z2: TOTALE RICHIESTO ANNO | AD2: PAGATO GEN-APR | AF2: NON PAGATO GEN-APR | AH2: PAGATO MAG-LUG | AJ2: PAGATO AGO-SET | AL2: PAGATO OTT-DIC | AN2: TOTALE PAGATO ANNO | AQ2: PERCENTUALE PAGAMENTO
B3: FER DIU | C3: FEST DIU | D3: FER DIU | E3: FEST DIU | F3: FER DIU | G3: FEST DIU | H3: FER DIU | I3: FEST DIU | J3: FER DIU | K3: FEST DIU | L3: FER DIU | M3: FEST DIU | N3: FER DIU | O3: FEST DIU | P3: FER DIU | Q3: FEST DIU | R3: FER DIU | S3: FEST DIU | T3: FER DIU | U3: FEST DIU | V3: FER DIU | W3: FEST DIU | X3: FER DIU | Y3: FEST DIU | Z3: FER DIU | AA3: FEST DIU | AD3: FER DIU | AE3: FEST DIU | AF3: FER DIU | AG3: FEST DIU | AH3: FER DIU | AI3: FEST DIU | AJ3: FER DIU | AK3: FEST DIU | AL3: FER DIU | AM3: FEST DIU | AN3: FER DIU | AO3: FEST DIU | AP3: TOTALE
A4: OMISSIS | B4: 32 | C4: 2 | D4: 32 | E4: 5 | F4: 40 | G4: 8 | H4: 50 | I4: 8 | J4: 12 | K4: 8 | L4: 32 | M4: 9 | N4: 34 | O4: 2 | P4: 44 | Q4: 13 | R4: 49 | S4: 7 | T4: 34 | U4: 17 | V4: 25 | W4: 5 | X4: 20 | Y4: 5 | Z4: =SUM(B4,D4,F4,H4,J4,L4,N4,P4,R4,T4,V4,X4) -> 404 | AA4: =SUM(C4,E4,G4,I4,K4,M4,O4,Q4,S4,U4,W4,Y4) -> 89 | AB4: =SUM(Z4:AA4) -> 493 | AD4: 123 | AE4: 18 | AF4: =B4+D4+F4+H4-AD4 -> 31 | AG4: =(C4+E4+G4+I4)-AE4 -> 5 | AH4: 87 | AI4: 18 | AJ4: 115 | AK4: 25 | AL4: 36 | AM4: 27 | AN4: =SUM(AD4,AF4,AH4,AJ4,AL4) -> 392 | AO4: =SUM(AE4,AG4,AI4,AK4,AM4) -> 93 | AP4: =(AN4+AO4) -> 485 | AQ4: =(AN4+AO4)/(Z4+AA4) -> 0.98377282
D5: 3 | E5: 0 | F5: 1 | G5: 0 | J5: 1 | K5: 0 | R5: 0 | S5: 4 | Z5: =SUM(B5,D5,F5,H5,J5,L5,N5,P5,R5,T5,V5,X5) -> 5 | AA5: =SUM(C5,E5,G5,I5,K5,M5,O5,Q5,S5,U5,W5,Y5) -> 4 | AB5: =SUM(Z5:AA5) -> 9 | AD5: 3 | AE5: 0 | AF5: =B5+D5+F5+H5-AD5 -> 1 | AG5: =(C5+E5+G5+I5)-AE5 -> 0 | AH5: 1 | AI5: 0 | AJ5: 1 | AK5: 4 | AN5: =SUM(AD5,AF5,AH5,AJ5,AL5) -> 6 | AO5: =SUM(AE5,AG5,AI5,AK5,AM5) -> 4 | AP5: =(AN5+AO5) -> 10 | AQ5: =(AN5+AO5)/(Z5+AA5) -> 1.1111111
B6: 6 | C6: 0 | D6: 1 | E6: 0 | H6: 3 | I6: 0 | J6: 0 | K6: 3 | N6: 6 | O6: 5 | P6: 2 | Q6: 0 | T6: 1 | U6: 0 | Z6: =SUM(B6,D6,F6,H6,J6,L6,N6,P6,R6,T6,V6,X6) -> 19 | AA6: =SUM(C6,E6,G6,I6,K6,M6,O6,Q6,S6,U6,W6,Y6) -> 8 | AB6: =SUM(Z6:AA6) -> 27 | AD6: 8 | AE6: 0 | AF6: =B6+D6+F6+H6-AD6 -> 2 | AG6: =(C6+E6+G6+I6)-AE6 -> 0 | AH6: 6 | AI6: 6 | AJ6: 4 | AK6: 2 | AN6: =SUM(AD6,AF6,AH6,AJ6,AL6) -> 20 | AO6: =SUM(AE6,AG6,AI6,AK6,AM6) -> 8 | AP6: =(AN6+AO6) -> 28 | AQ6: =(AN6+AO6)/(Z6+AA6) -> 1.037037
P7: 2 | Q7: 0 | T7: 4 | U7: 0 | Z7: =SUM(B7,D7,F7,H7,J7,L7,N7,P7,R7,T7,V7,X7) -> 6 | AA7: =SUM(C7,E7,G7,I7,K7,M7,O7,Q7,S7,U7,W7,Y7) -> 0 | AB7: =SUM(Z7:AA7) -> 6 | AF7: =B7+D7+F7+H7-AD7 -> 0 | AG7: =(C7+E7+G7+I7)-AE7 -> 0 | AJ7: 2 | AK7: 0 | AL7: 3 | AN7: =SUM(AD7,AF7,AH7,AJ7,AL7) -> 5 | AO7: =SUM(AE7,AG7,AI7,AK7,AM7) -> 0 | AP7: =(AN7+AO7) -> 5 | AQ7: =(AN7+AO7)/(Z7+AA7) -> 0.83333333
Z8: =SUM(B8,D8,F8,H8,J8,L8,N8,P8,R8,T8,V8,X8) -> 0 | AA8: =SUM(C8,E8,G8,I8,K8,M8,O8,Q8,S8,U8,W8,Y8) -> 0 | AB8: =SUM(Z8:AA8) -> 0 | AF8: =B8+D8+F8+H8-AD8 -> 0 | AG8: =(C8+E8+G8+I8)-AE8 -> 0 | AN8: =SUM(AD8,AF8,AH8,AJ8,AL8) -> 0 | AO8: =SUM(AE8,AG8,AI8,AK8,AM8) -> 0 | AP8: =(AN8+AO8) -> 0
H9: 3 | I9: 0 | Z9: =SUM(B9,D9,F9,H9,J9,L9,N9,P9,R9,T9,V9,X9) -> 3 | AA9: =SUM(C9,E9,G9,I9,K9,M9,O9,Q9,S9,U9,W9,Y9) -> 0 | AB9: =SUM(Z9:AA9) -> 3 | AF9: =B9+D9+F9+H9-AD9 -> 3 | AG9: =(C9+E9+G9+I9)-AE9 -> 0 | AJ9: 1 | AK9: 0 | AN9: =SUM(AD9,AF9,AH9,AJ9,AL9) -> 4 | AO9: =SUM(AE9,AG9,AI9,AK9,AM9) -> 0 | AP9: =(AN9+AO9) -> 4 | AQ9: =(AN9+AO9)/(Z9+AA9) -> 1.3333333
Z10: =SUM(B10,D10,F10,H10,J10,L10,N10,P10,R10,T10,V10,X10) -> 0 | AA10: =SUM(C10,E10,G10,I10,K10,M10,O10,Q10,S10,U10,W10,Y10) -> 0 | AB10: =SUM(Z10:AA10) -> 0 | AF10: =B10+D10+F10+H10-AD10 -> 0 | AG10: =(C10+E10+G10+I10)-AE10 -> 0 | AN10: =SUM(AD10,AF10,AH10,AJ10,AL10) -> 0 | AO10: =SUM(AE10,AG10,AI10,AK10,AM10) -> 0 | AP10: =(AN10+AO10) -> 0
D11: 3 | E11: 0 | F11: 3 | G11: 0 | J11: 8 | K11: 3 | L11: 3 | M11: 0 | N11: 5 | O11: 0 | P11: 3 | Q11: 5 | T11: 2 | U11: 0 | V11: 2 | W11: 0 | Z11: =SUM(B11,D11,F11,H11,J11,L11,N11,P11,R11,T11,V11,X11) -> 29 | AA11: =SUM(C11,E11,G11,I11,K11,M11,O11,Q11,S11,U11,W11,Y11) -> 8 | AB11: =SUM(Z11:AA11) -> 37 | AD11: 4 | AE11: 0 | AF11: =B11+D11+F11+H11-AD11 -> 2 | AG11: =(C11+E11+G11+I11)-AE11 -> 0 | AH11: 14 | AI11: 2 | AJ11: 7 | AK11: 6 | AL11: 3 | AN11: =SUM(AD11,AF11,AH11,AJ11,AL11) -> 30 | AO11: =SUM(AE11,AG11,AI11,AK11,AM11) -> 8 | AP11: =(AN11+AO11) -> 38 | AQ11: =(AN11+AO11)/(Z11+AA11) -> 1.027027
Z12: =SUM(B12,D12,F12,H12,J12,L12,N12,P12,R12,T12,V12,X12) -> 0 | AA12: =SUM(C12,E12,G12,I12,K12,M12,O12,Q12,S12,U12,W12,Y12) -> 0 | AB12: =SUM(Z12:AA12) -> 0 | AD12: 0 | AE12: 0 | AF12: =B12+D12+F12+H12-AD12 -> 0 | AG12: =(C12+E12+G12+I12)-AE12 -> 0 | AH12: 3 | AI12: 0 | AN12: =SUM(AD12,AF12,AH12,AJ12,AL12) -> 3 | AO12: =SUM(AE12,AG12,AI12,AK12,AM12) -> 0 | AP12: =(AN12+AO12) -> 3
J13: 0 | K13: 4 | P13: 2 | Q13: 2 | Z13: =SUM(B13,D13,F13,H13,J13,L13,N13,P13,R13,T13,V13,X13) -> 2 | AA13: =SUM(C13,E13,G13,I13,K13,M13,O13,Q13,S13,U13,W13,Y13) -> 6 | AB13: =SUM(Z13:AA13) -> 8 | AD13: 0 | AE13: 0 | AF13: =B13+D13+F13+H13-AD13 -> 0 | AG13: =(C13+E13+G13+I13)-AE13 -> 0 | AH13: 3 | AI13: 0 | AJ13: 2 | AK13: 3 | AN13: =SUM(AD13,AF13,AH13,AJ13,AL13) -> 5 | AO13: =SUM(AE13,AG13,AI13,AK13,AM13) -> 3 | AP13: =(AN13+AO13) -> 8 | AQ13: =(AN13+AO13)/(Z13+AA13) -> 1
N14: 4 | O14: 0 | Z14: =SUM(B14,D14,F14,H14,J14,L14,N14,P14,R14,T14,V14,X14) -> 4 | AA14: =SUM(C14,E14,G14,I14,K14,M14,O14,Q14,S14,U14,W14,Y14) -> 0 | AB14: =SUM(Z14:AA14) -> 4 | AF14: =B14+D14+F14+H14-AD14 -> 0 | AG14: =(C14+E14+G14+I14)-AE14 -> 0 | AJ14: 1 | AK14: 0 | AN14: =SUM(AD14,AF14,AH14,AJ14,AL14) -> 1 | AO14: =SUM(AE14,AG14,AI14,AK14,AM14) -> 0 | AP14: =(AN14+AO14) -> 1 | AQ14: =(AN14+AO14)/(Z14+AA14) -> 0.25
H15: 3 | I15: 0 | Z15: =SUM(B15,D15,F15,H15,J15,L15,N15,P15,R15,T15,V15,X15) -> 3 | AA15: =SUM(C15,E15,G15,I15,K15,M15,O15,Q15,S15,U15,W15,Y15) -> 0 | AB15: =SUM(Z15:AA15) -> 3 | AF15: =B15+D15+F15+H15-AD15 -> 3 | AG15: =(C15+E15+G15+I15)-AE15 -> 0 | AJ15: 1 | AK15: 0 | AN15: =SUM(AD15,AF15,AH15,AJ15,AL15) -> 4 | AO15: =SUM(AE15,AG15,AI15,AK15,AM15) -> 0 | AP15: =(AN15+AO15) -> 4 | AQ15: =(AN15+AO15)/(Z15+AA15) -> 1.3333333
T16: 4 | U16: 0 | V16: 1 | W16: 0 | Z16: =SUM(B16,D16,F16,H16,J16,L16,N16,P16,R16,T16,V16,X16) -> 5 | AA16: =SUM(C16,E16,G16,I16,K16,M16,O16,Q16,S16,U16,W16,Y16) -> 0 | AB16: =SUM(Z16:AA16) -> 5 | AF16: =B16+D16+F16+H16-AD16 -> 0 | AG16: =(C16+E16+G16+I16)-AE16 -> 0 | AL16: 4 | AN16: =SUM(AD16,AF16,AH16,AJ16,AL16) -> 4 | AO16: =SUM(AE16,AG16,AI16,AK16,AM16) -> 0 | AP16: =(AN16+AO16) -> 4 | AQ16: =(AN16+AO16)/(Z16+AA16) -> 0.8
B17: 7 | C17: 0 | H17: 2 | I17: 0 | N17: 3 | O17: 0 | Z17: =SUM(B17,D17,F17,H17,J17,L17,N17,P17,R17,T17,V17,X17) -> 12 | AA17: =SUM(C17,E17,G17,I17,K17,M17,O17,Q17,S17,U17,W17,Y17) -> 0 | AB17: =SUM(Z17:AA17) -> 12 | AD17: 7 | AE17: 0 | AF17: =B17+D17+F17+H17-AD17 -> 2 | AG17: =(C17+E17+G17+I17)-AE17 -> 0 | AH17: 0 | AI17: 0 | AJ17: 1 | AK17: 0 | AN17: =SUM(AD17,AF17,AH17,AJ17,AL17) -> 10 | AO17: =SUM(AE17,AG17,AI17,AK17,AM17) -> 0 | AP17: =(AN17+AO17) -> 10 | AQ17: =(AN17+AO17)/(Z17+AA17) -> 0.83333333
Z18: =SUM(B18,D18,F18,H18,J18,L18,N18,P18,R18,T18,V18,X18) -> 0 | AA18: =SUM(C18,E18,G18,I18,K18,M18,O18,Q18,S18,U18,W18,Y18) -> 0 | AB18: =SUM(Z18:AA18) -> 0 | AF18: =B18+D18+F18+H18-AD18 -> 0 | AG18: =(C18+E18+G18+I18)-AE18 -> 0 | AN18: =SUM(AD18,AF18,AH18,AJ18,AL18) -> 0 | AO18: =SUM(AE18,AG18,AI18,AK18,AM18) -> 0 | AP18: =(AN18+AO18) -> 0
Z19: =SUM(B19,D19,F19,H19,J19,L19,N19,P19,R19,T19,V19,X19) -> 0 | AA19: =SUM(C19,E19,G19,I19,K19,M19,O19,Q19,S19,U19,W19,Y19) -> 0 | AB19: =SUM(Z19:AA19) -> 0 | AF19: =B19+D19+F19+H19-AD19 -> 0 | AG19: =(C19+E19+G19+I19)-AE19 -> 0 | AN19: =SUM(AD19,AF19,AH19,AJ19,AL19) -> 0 | AO19: =SUM(AE19,AG19,AI19,AK19,AM19) -> 0 | AP19: =(AN19+AO19) -> 0
Z20: =SUM(B20,D20,F20,H20,J20,L20,N20,P20,R20,T20,V20,X20) -> 0 | AA20: =SUM(C20,E20,G20,I20,K20,M20,O20,Q20,S20,U20,W20,Y20) -> 0 | AB20: =SUM(Z20:AA20) -> 0 | AF20: =B20+D20+F20+H20-AD20 -> 0 | AG20: =(C20+E20+G20+I20)-AE20 -> 0 | AN20: =SUM(AD20,AF20,AH20,AJ20,AL20) -> 0 | AO20: =SUM(AE20,AG20,AI20,AK20,AM20) -> 0 | AP20: =(AN20+AO20) -> 0
Z21: =SUM(B21,D21,F21,H21,J21,L21,N21,P21,R21,T21,V21,X21) -> 0 | AA21: =SUM(C21,E21,G21,I21,K21,M21,O21,Q21,S21,U21,W21,Y21) -> 0 | AB21: =SUM(Z21:AA21) -> 0 | AF21: =B21+D21+F21+H21-AD21 -> 0 | AG21: =(C21+E21+G21+I21)-AE21 -> 0 | AN21: =SUM(AD21,AF21,AH21,AJ21,AL21) -> 0 | AO21: =SUM(AE21,AG21,AI21,AK21,AM21) -> 0 | AP21: =(AN21+AO21) -> 0
F22: 2 | G22: 0 | J22: 0 | K22: 2 | Z22: =SUM(B22,D22,F22,H22,J22,L22,N22,P22,R22,T22,V22,X22) -> 2 | AA22: =SUM(C22,E22,G22,I22,K22,M22,O22,Q22,S22,U22,W22,Y22) -> 2 | AB22: =SUM(Z22:AA22) -> 4 | AD22: 1 | AE22: 0 | AF22: =B22+D22+F22+H22-AD22 -> 1 | AG22: =(C22+E22+G22+I22)-AE22 -> 0 | AH22: 0 | AI22: 1 | AJ22: 1 | AK22: 1 | AN22: =SUM(AD22,AF22,AH22,AJ22,AL22) -> 3 | AO22: =SUM(AE22,AG22,AI22,AK22,AM22) -> 2 | AP22: =(AN22+AO22) -> 5 | AQ22: =(AN22+AO22)/(Z22+AA22) -> 1.25
Z23: =SUM(B23,D23,F23,H23,J23,L23,N23,P23,R23,T23,V23,X23) -> 0 | AA23: =SUM(C23,E23,G23,I23,K23,M23,O23,Q23,S23,U23,W23,Y23) -> 0 | AB23: =SUM(Z23:AA23) -> 0 | AF23: =B23+D23+F23+H23-AD23 -> 0 | AG23: =(C23+E23+G23+I23)-AE23 -> 0 | AN23: =SUM(AD23,AF23,AH23,AJ23,AL23) -> 0 | AO23: =SUM(AE23,AG23,AI23,AK23,AM23) -> 0 | AP23: =(AN23+AO23) -> 0
H24: 3 | I24: 0 | Z24: =SUM(B24,D24,F24,H24,J24,L24,N24,P24,R24,T24,V24,X24) -> 3 | AA24: =SUM(C24,E24,G24,I24,K24,M24,O24,Q24,S24,U24,W24,Y24) -> 0 | AB24: =SUM(Z24:AA24) -> 3 | AF24: =B24+D24+F24+H24-AD24 -> 3 | AG24: =(C24+E24+G24+I24)-AE24 -> 0 | AJ24: 1 | AK24: 0 | AN24: =SUM(AD24,AF24,AH24,AJ24,AL24) -> 4 | AO24: =SUM(AE24,AG24,AI24,AK24,AM24) -> 0 | AP24: =(AN24+AO24) -> 4 | AQ24: =(AN24+AO24)/(Z24+AA24) -> 1.3333333
T25: 4 | U25: 0 | Z25: =SUM(B25,D25,F25,H25,J25,L25,N25,P25,R25,T25,V25,X25) -> 4 | AA25: =SUM(C25,E25,G25,I25,K25,M25,O25,Q25,S25,U25,W25,Y25) -> 0 | AB25: =SUM(Z25:AA25) -> 4 | AF25: =B25+D25+F25+H25-AD25 -> 0 | AG25: =(C25+E25+G25+I25)-AE25 -> 0 | AL25: 3 | AN25: =SUM(AD25,AF25,AH25,AJ25,AL25) -> 3 | AO25: =SUM(AE25,AG25,AI25,AK25,AM25) -> 0 | AP25: =(AN25+AO25) -> 3 | AQ25: =(AN25+AO25)/(Z25+AA25) -> 0.75
Z26: =SUM(B26,D26,F26,H26,J26,L26,N26,P26,R26,T26,V26,X26) -> 0 | AA26: =SUM(C26,E26,G26,I26,K26,M26,O26,Q26,S26,U26,W26,Y26) -> 0 | AB26: =SUM(Z26:AA26) -> 0 | AF26: =B26+D26+F26+H26-AD26 -> 0 | AG26: =(C26+E26+G26+I26)-AE26 -> 0 | AN26: =SUM(AD26,AF26,AH26,AJ26,AL26) -> 0 | AO26: =SUM(AE26,AG26,AI26,AK26,AM26) -> 0 | AP26: =(AN26+AO26) -> 0
Z27: =SUM(B27,D27,F27,H27,J27,L27,N27,P27,R27,T27,V27,X27) -> 0 | AA27: =SUM(C27,E27,G27,I27,K27,M27,O27,Q27,S27,U27,W27,Y27) -> 0 | AB27: =SUM(Z27:AA27) -> 0 | AF27: =B27+D27+F27+H27-AD27 -> 0 | AG27: =(C27+E27+G27+I27)-AE27 -> 0 | AN27: =SUM(AD27,AF27,AH27,AJ27,AL27) -> 0 | AO27: =SUM(AE27,AG27,AI27,AK27,AM27) -> 0 | AP27: =(AN27+AO27) -> 0
D28: 3 | E28: 0 | F28: 3 | G28: 0 | H28: 9 | I28: 3 | J28: 2 | K28: 6 | L28: 18 | M28: 10 | N28: 9 | O28: 10 | P28: 1 | Q28: 16 | R28: 0 | S28: 5 | Z28: =SUM(B28,D28,F28,H28,J28,L28,N28,P28,R28,T28,V28,X28) -> 45 | AA28: =SUM(C28,E28,G28,I28,K28,M28,O28,Q28,S28,U28,W28,Y28) -> 50 | AB28: =SUM(Z28:AA28) -> 95 | AD28: 12 | AE28: 2 | AF28: =B28+D28+F28+H28-AD28 -> 3 | AG28: =(C28+E28+G28+I28)-AE28 -> 1 | AH28: 25 | AI28: 21 | AJ28: 8 | AK28: 27 | AN28: =SUM(AD28,AF28,AH28,AJ28,AL28) -> 48 | AO28: =SUM(AE28,AG28,AI28,AK28,AM28) -> 51 | AP28: =(AN28+AO28) -> 99 | AQ28: =(AN28+AO28)/(Z28+AA28) -> 1.0421053
H29: 9 | I29: 0 | J29: 8 | K29: 6 | L29: 12 | M29: 6 | P29: 12 | Q29: 14 | Z29: =SUM(B29,D29,F29,H29,J29,L29,N29,P29,R29,T29,V29,X29) -> 41 | AA29: =SUM(C29,E29,G29,I29,K29,M29,O29,Q29,S29,U29,W29,Y29) -> 26 | AB29: =SUM(Z29:AA29) -> 67 | AD29: 7 | AE29: 0 | AF29: =B29+D29+F29+H29-AD29 -> 2 | AG29: =(C29+E29+G29+I29)-AE29 -> 0 | AH29: 17 | AI29: 9 | AJ29: 17 | AK29: 17 | AN29: =SUM(AD29,AF29,AH29,AJ29,AL29) -> 43 | AO29: =SUM(AE29,AG29,AI29,AK29,AM29) -> 26 | AP29: =(AN29+AO29) -> 69 | AQ29: =(AN29+AO29)/(Z29+AA29) -> 1.0298507
B30: 6 | C30: 0 | D30: 2 | E30: 0 | F30: 1 | G30: 2 | H30: 7 | I30: 4 | J30: 6 | K30: 4 | L30: 22 | M30: 5 | N30: 5 | O30: 0 | T30: 17 | U30: 0 | Z30: =SUM(B30,D30,F30,H30,J30,L30,N30,P30,R30,T30,V30,X30) -> 66 | AA30: =SUM(C30,E30,G30,I30,K30,M30,O30,Q30,S30,U30,W30,Y30) -> 15 | AB30: =SUM(Z30:AA30) -> 81 | AD30: 29 | AE30: 8 | AF30: =B30+D30+F30+H30-AD30 -> -13 | AG30: =(C30+E30+G30+I30)-AE30 -> -2 | AH30: 12 | AI30: 4 | AJ30: 8 | AK30: 3 | AL30: 16 | AN30: =SUM(AD30,AF30,AH30,AJ30,AL30) -> 52 | AO30: =SUM(AE30,AG30,AI30,AK30,AM30) -> 13 | AP30: =(AN30+AO30) -> 65 | AQ30: =(AN30+AO30)/(Z30+AA30) -> 0.80246914
R31: 4 | S31: 0 | Z31: =SUM(B31,D31,F31,H31,J31,L31,N31,P31,R31,T31,V31,X31) -> 4 | AA31: =SUM(C31,E31,G31,I31,K31,M31,O31,Q31,S31,U31,W31,Y31) -> 0 | AB31: =SUM(Z31:AA31) -> 4 | AF31: =B31+D31+F31+H31-AD31 -> 0 | AG31: =(C31+E31+G31+I31)-AE31 -> 0 | AJ31: 4 | AK31: 0 | AN31: =SUM(AD31,AF31,AH31,AJ31,AL31) -> 4 | AO31: =SUM(AE31,AG31,AI31,AK31,AM31) -> 0 | AP31: =(AN31+AO31) -> 4 | AQ31: =(AN31+AO31)/(Z31+AA31) -> 1
Z32: =SUM(B32,D32,F32,H32,J32,L32,N32,P32,R32,T32,V32,X32) -> 0 | AA32: =SUM(C32,E32,G32,I32,K32,M32,O32,Q32,S32,U32,W32,Y32) -> 0 | AB32: =SUM(Z32:AA32) -> 0 | AF32: =B32+D32+F32+H32-AD32 -> 0 | AG32: =(C32+E32+G32+I32)-AE32 -> 0 | AN32: =SUM(AD32,AF32,AH32,AJ32,AL32) -> 0 | AO32: =SUM(AE32,AG32,AI32,AK32,AM32) -> 0 | AP32: =(AN32+AO32) -> 0
F33: 6 | G33: 6 | H33: 9 | I33: 2 | L33: 4 | M33: 9 | N33: 3 | O33: 6 | Z33: =SUM(B33,D33,F33,H33,J33,L33,N33,P33,R33,T33,V33,X33) -> 22 | AA33: =SUM(C33,E33,G33,I33,K33,M33,O33,Q33,S33,U33,W33,Y33) -> 23 | AB33: =SUM(Z33:AA33) -> 45 | AD33: 12 | AE33: 6 | AF33: =B33+D33+F33+H33-AD33 -> 3 | AG33: =(C33+E33+G33+I33)-AE33 -> 2 | AH33: 8 | AI33: 8 | AJ33: 2 | AK33: 3 | AN33: =SUM(AD33,AF33,AH33,AJ33,AL33) -> 25 | AO33: =SUM(AE33,AG33,AI33,AK33,AM33) -> 19 | AP33: =(AN33+AO33) -> 44 | AQ33: =(AN33+AO33)/(Z33+AA33) -> 0.97777778
N34: 7 | O34: 9 | P34: 2 | Q34: 16 | Z34: =SUM(B34,D34,F34,H34,J34,L34,N34,P34,R34,T34,V34,X34) -> 9 | AA34: =SUM(C34,E34,G34,I34,K34,M34,O34,Q34,S34,U34,W34,Y34) -> 25 | AB34: =SUM(Z34:AA34) -> 34 | AF34: =B34+D34+F34+H34-AD34 -> 0 | AG34: =(C34+E34+G34+I34)-AE34 -> 0 | AH34: 5 | AI34: 7 | AJ34: 4 | AK34: 18 | AN34: =SUM(AD34,AF34,AH34,AJ34,AL34) -> 9 | AO34: =SUM(AE34,AG34,AI34,AK34,AM34) -> 25 | AP34: =(AN34+AO34) -> 34 | AQ34: =(AN34+AO34)/(Z34+AA34) -> 1
H35: 5 | I35: 0 | J35: 3 | K35: 4 | P35: 4 | Q35: 7 | Z35: =SUM(B35,D35,F35,H35,J35,L35,N35,P35,R35,T35,V35,X35) -> 12 | AA35: =SUM(C35,E35,G35,I35,K35,M35,O35,Q35,S35,U35,W35,Y35) -> 11 | AB35: =SUM(Z35:AA35) -> 23 | AD35: 3 | AE35: 3 | AF35: =B35+D35+F35+H35-AD35 -> 2 | AG35: =(C35+E35+G35+I35)-AE35 -> -3 | AH35: 4 | AI35: 0 | AJ35: 5 | AK35: 8 | AN35: =SUM(AD35,AF35,AH35,AJ35,AL35) -> 14 | AO35: =SUM(AE35,AG35,AI35,AK35,AM35) -> 8 | AP35: =(AN35+AO35) -> 22 | AQ35: =(AN35+AO35)/(Z35+AA35) -> 0.95652174
Z36: =SUM(B36,D36,F36,H36,J36,L36,N36,P36,R36,T36,V36,X36) -> 0 | AA36: =SUM(C36,E36,G36,I36,K36,M36,O36,Q36,S36,U36,W36,Y36) -> 0 | AB36: =SUM(Z36:AA36) -> 0 | AF36: =B36+D36+F36+H36-AD36 -> 0 | AG36: =(C36+E36+G36+I36)-AE36 -> 0 | AN36: =SUM(AD36,AF36,AH36,AJ36,AL36) -> 0 | AO36: =SUM(AE36,AG36,AI36,AK36,AM36) -> 0 | AP36: =(AN36+AO36) -> 0
H37: 2 | I37: 3 | J37: 0 | K37: 5 | N37: 13 | O37: 10 | P37: 0 | Q37: 5 | Z37: =SUM(B37,D37,F37,H37,J37,L37,N37,P37,R37,T37,V37,X37) -> 15 | AA37: =SUM(C37,E37,G37,I37,K37,M37,O37,Q37,S37,U37,W37,Y37) -> 23 | AB37: =SUM(Z37:AA37) -> 38 | AD37: 1 | AE37: 2 | AF37: =B37+D37+F37+H37-AD37 -> 1 | AG37: =(C37+E37+G37+I37)-AE37 -> 1 | AH37: 11 | AI37: 12 | AJ37: 3 | AK37: 9 | AN37: =SUM(AD37,AF37,AH37,AJ37,AL37) -> 16 | AO37: =SUM(AE37,AG37,AI37,AK37,AM37) -> 24 | AP37: =(AN37+AO37) -> 40 | AQ37: =(AN37+AO37)/(Z37+AA37) -> 1.0526316
H38: 2 | I38: 4 | J38: 0 | K38: 5 | L38: 3 | M38: 0 | N38: 11 | O38: 5 | P38: 2 | Q38: 25 | Z38: =SUM(B38,D38,F38,H38,J38,L38,N38,P38,R38,T38,V38,X38) -> 18 | AA38: =SUM(C38,E38,G38,I38,K38,M38,O38,Q38,S38,U38,W38,Y38) -> 39 | AB38: =SUM(Z38:AA38) -> 57 | AD38: 1 | AE38: 3 | AF38: =B38+D38+F38+H38-AD38 -> 1 | AG38: =(C38+E38+G38+I38)-AE38 -> 1 | AH38: 12 | AI38: 8 | AJ38: 5 | AK38: 28 | AN38: =SUM(AD38,AF38,AH38,AJ38,AL38) -> 19 | AO38: =SUM(AE38,AG38,AI38,AK38,AM38) -> 40 | AP38: =(AN38+AO38) -> 59 | AQ38: =(AN38+AO38)/(Z38+AA38) -> 1.0350877
H39: 0 | I39: 4 | N39: 5 | O39: 0 | P39: 3 | Q39: 13 | Z39: =SUM(B39,D39,F39,H39,J39,L39,N39,P39,R39,T39,V39,X39) -> 8 | AA39: =SUM(C39,E39,G39,I39,K39,M39,O39,Q39,S39,U39,W39,Y39) -> 17 | AB39: =SUM(Z39:AA39) -> 25 | AD39: 0 | AE39: 3 | AF39: =B39+D39+F39+H39-AD39 -> 0 | AG39: =(C39+E39+G39+I39)-AE39 -> 1 | AH39: 1 | AI39: 0 | AJ39: 4 | AK39: 14 | AN39: =SUM(AD39,AF39,AH39,AJ39,AL39) -> 5 | AO39: =SUM(AE39,AG39,AI39,AK39,AM39) -> 18 | AP39: =(AN39+AO39) -> 23 | AQ39: =(AN39+AO39)/(Z39+AA39) -> 0.92
H40: 9 | I40: 0 | L40: 4 | M40: 11 | N40: 11 | O40: 12 | P40: 1 | Q40: 42 | Z40: =SUM(B40,D40,F40,H40,J40,L40,N40,P40,R40,T40,V40,X40) -> 25 | AA40: =SUM(C40,E40,G40,I40,K40,M40,O40,Q40,S40,U40,W40,Y40) -> 65 | AB40: =SUM(Z40:AA40) -> 90 | AD40: 7 | AE40: 0 | AF40: =B40+D40+F40+H40-AD40 -> 2 | AG40: =(C40+E40+G40+I40)-AE40 -> 0 | AH40: 13 | AI40: 18 | AJ40: 5 | AK40: 47 | AN40: =SUM(AD40,AF40,AH40,AJ40,AL40) -> 27 | AO40: =SUM(AE40,AG40,AI40,AK40,AM40) -> 65 | AP40: =(AN40+AO40) -> 92 | AQ40: =(AN40+AO40)/(Z40+AA40) -> 1.0222222
...

Sheet Confronto ore 2024_2025
B2: Id Dipendente | C2: Eccedenze al 31/12/2024 | D2: Eccedenze al 31/12/2025 | E2: Differenza (-)
B3: ID_DIP_001 | C3: 0.90277778 | D3: 0 | E3: ='Confronto ore 2024_2025'!$C3-'Confronto ore 2024_2025'!$D3 -> 0.90277778 | G3: MEDIA ECCEDENZE ORARIE AL 31/12/2024
B4: ID_DIP_002 | C4: 0 | D4: 0 | E4: ='Confronto ore 2024_2025'!$C4-'Confronto ore 2024_2025'!$D4 -> 0 | G4: =AVERAGE('Confronto ore 2024_2025'!$C$3:$C$14) -> 3.970544
B5: ID_DIP_003 | C5: 1.6597222 | D5: 0.45833333 | E5: ='Confronto ore 2024_2025'!$C5-'Confronto ore 2024_2025'!$D5 -> 1.2013889
B6: ID_DIP_004 | C6: 0.39791667 | D6: 0 | E6: ='Confronto ore 2024_2025'!$C6-'Confronto ore 2024_2025'!$D6 -> 0.39791667
B7: ID_DIP_005 | C7: 4.2708333 | D7: 1.125 | E7: ='Confronto ore 2024_2025'!$C7-'Confronto ore 2024_2025'!$D7 -> 3.1458333 | G7: MEDIA ECCEDENZE ORARIE AL 31/12/2025
B8: ID_DIP_006 | C8: 6.84375 | D8: 3.75 | E8: ='Confronto ore 2024_2025'!$C8-'Confronto ore 2024_2025'!$D8 -> 3.09375 | G8: =AVERAGE('Confronto ore 2024_2025'!$D$3:$D$14) -> 1.6180556
B9: ID_DIP_007 | C9: 1.5069444 | D9: 1.5 | E9: ='Confronto ore 2024_2025'!$C9-'Confronto ore 2024_2025'!$D9 -> 0.0069444444
B10: ID_DIP_008 | C10: 7.7354167 | D10: 2.9166667 | E10: ='Confronto ore 2024_2025'!$C10-'Confronto ore 2024_2025'!$D10 -> 4.81875
B11: ID_DIP_009 | C11: 6.4270833 | D11: 1.9583333 | E11: ='Confronto ore 2024_2025'!$C11-'Confronto ore 2024_2025'!$D11 -> 4.46875 | G11: DIFFERENZA MEDIA
B12: ID_DIP_010 | C12: 4.46875 | D12: 1.4166667 | E12: ='Confronto ore 2024_2025'!$C12-'Confronto ore 2024_2025'!$D12 -> 3.0520833 | G12: =(('Confronto ore 2024_2025'!$D$15-'Confronto ore 2024_2025'!$C$15)/'Confronto ore 2024_2025'!$C$15) -> -0.59248517
B13: ID_DIP_011 | C13: 6.2430556 | D13: 3.0416667 | E13: ='Confronto ore 2024_2025'!$C13-'Confronto ore 2024_2025'!$D13 -> 3.2013889
B14: ID_DIP_012 | C14: 7.1902778 | D14: 3.25 | E14: ='Confronto ore 2024_2025'!$C14-'Confronto ore 2024_2025'!$D14 -> 3.9402778
B15: TOTALE | C15: =SUBTOTAL(109,'Confronto ore 2024_2025'!$C$3:$C$14) -> 47.646528 | D15: =SUBTOTAL(109,'Confronto ore 2024_2025'!$D$3:$D$14) -> 19.416667 | E15: =SUBTOTAL(109,'Confronto ore 2024_2025'!$E$3:$E$14) -> 28.229861
G17: Calcolo del Risparmio (ROI Analysis)
G18: Voce | H18: Dati 2024 | I18: Dati 2025 | J18: Differenza (Risparmio)
G19: Monte Ore Straordinari | H19: 1.460 ore | I19: 1.108 ore | J19: -352 ore
G20: Costo Totale (~24€/h) | H20: 35040 | I20: 26592 | J20: 8448
G24: Analisi dell'Investimento
G25: Costo Implementazione: 6.000 €
G26: Risparmio Generato (1° anno): 8.448 €
G28: ROI (Ritorno sull'Investimento): +41%

Sheet Grafico
B44: CONFRONTO PAGAMENTI MENSILI 2023/2025
B46: 2025
B47: GENNAIO | C47: FEBBRAIO | D47: MARZO | E47: APRILE | F47: MAGGIO | G47: GIUGNO | H47: LUGLIO | I47: AGOSTO | J47: SETTEMBRE | K47: OTTOBRE | L47: NOVEMBRE | M47: DICEMBRE | N47: TOTALE 2025
B48: 12 | C48: 17 | D48: 36 | E48: 64 | F48: 143 | G48: 250 | H48: 213 | I48: 199 | J48: 31 | K48: 70 | L48: 37 | M48: 36 | N48: =SUM(B48:M48) -> 1108
B50: 2024
B51: GENNAIO | C51: FEBBRAIO | D51: MARZO | E51: APRILE | F51: MAGGIO | G51: GIUGNO | H51: LUGLIO | I51: AGOSTO | J51: SETTEMBRE | K51: OTTOBRE | L51: NOVEMBRE | M51: DICEMBRE | N51: TOTALE 2024
B52: 53 | C52: 51 | D52: 74 | E52: 144 | F52: 120 | G52: 308 | H52: 290 | I52: 389 | J52: 81 | K52: 104 | L52: 33 | M52: 30 | N52: =SUM(B52:M52) -> 1677
B54: 2023
B55: GENNAIO | C55: FEBBRAIO | D55: MARZO | E55: APRILE | F55: MAGGIO | G55: GIUGNO | H55: LUGLIO | I55: AGOSTO | J55: SETTEMBRE | K55: OTTOBRE | L55: NOVEMBRE | M55: DICEMBRE | N55: TOTALE 2023
B56: 29 | C56: 37 | D56: 22 | E56: 77 | F56: 135 | G56: 105 | H56: 317 | I56: 453 | J56: 112 | K56: 58 | L56: 59 | M56: 56 | N56: =SUM(B56:M56) -> 1460

Sheet Dashboard_Finale
